Workbook

Sheet 00_Cover
B2: Northline Consumer Products
B3: Capex investment case · Plant 2 RTD Line 4 · NPV, IRR, payback
B4: FY2026–2034 · unlevered project cash flows · fictional CPG company · $000s
B6: What this file is
B7: An investment-committee pack for a fictional high-speed RTD filling line at Plant 2. Capex is timed over two years. Benefits are incremental volume × contribution per case plus run-rate cost savings (labor, scrap, energy, avoided maintenance on the old line). Cash flows are unlevered: NOPAT + D&A − capex − ΔNWC + after-tax salvage. Returns (NPV, IRR, payback, PI) and a WACC × volume sensitivity sit on formulas. A Base / Upside / Downside toggle scales capex, volume, savings, and contribution.
B9: How to use
B10: 1. Edit yellow cells on 01_Assumptions (scenario, WACC, tax, life, capex timing, volume ramp, unit economics, savings).
B11: 2. Read the unlevered cash-flow build on 02_Cash_Flows (all formulas from Assumptions).
B12: 3. Read NPV, IRR, payback, and PI on 03_Returns.
B13: 4. Stress WACC and volume on 04_Sensitivity (one-way, two-way, tornado).
B14: 5. Use 05_One_Pager as the investment-committee snapshot.
B16: File conventions
... B23: https://github.com/saisiri-bandaru

Sheet 01_Assumptions
B2: Assumptions
B3: Yellow + blue = inputs. Scenario, WACC, capex timing, volume ramp, and unit economics drive every other tab.
B5: Control panel
B6: Scenario (1 = Base, 2 = Upside, 3 = Downside) | C6: 1 | D6: =INDEX({"Base","Upside","Downside"},1,C6) | E6: Scales capex, volume, savings, and contribution $/case.
B7: Capex factor | C7: =INDEX($D$15:$D$17,$C$6)
B8: Volume factor | C8: =INDEX($E$15:$E$17,$C$6)
B9: Savings factor | C9: =INDEX($F$15:$F$17,$C$6)
B10: Contribution factor (on $/case) | C10: =INDEX($G$15:$G$17,$C$6)
B12: Scenario table (inputs)
B13: # | C13: Name | D13: Capex | E13: Volume | F13: Savings | G13: Contrib $/case
B15: 1 | C15: Base | D15: 1 | E15: 1 | F15: 1 | G15: 1
B16: 2 | C16: Upside | D16: 0.95 | E16: 1.12 | F16: 1.08 | G16: 1.03
B17: 3 | C17: Downside | D17: 1.12 | E17: 0.85 | F17: 0.9 | G17: 0.97
B19: Project
B20: Project name | C20: Plant 2 — RTD Line 4 (high-speed filling)
B21: Sponsor / site | C21: Operations / Supply Chain · Midwest Plant 2
B22: In-service (COD) year | C22: 2027
B24: Returns, tax, NWC, salvage
B25: WACC | C25: 0.095 | D25: Unlevered project hurdle. Sample 9.5%.
B26: Tax rate | C26: 0.25
B27: Project life (years) | C27: 8 | D27: D&A and operating life from COD (t = 1..life). Sample through 2034.
B28: Salvage % of gross capex | C28: 0.08
B29: NWC % of incremental revenue | C29: 0.065
B30: Incremental G&A ($000s / year from COD) | C30: 80
B32: Year-by-year drivers
B33: Driver | C33: 2026 | D33: 2027 | E33: 2028 | F33: 2029 | G33: 2030 | H33: 2031 | I33: 2032 | J33: 2033 | K33: 2034
B34: Time index t | C34: 0 | D34: 1 | E34: 2 | F34: 3 | G34: 4 | H34: 5 | I34: 6 | J34: 7 | K34: 8
B35: Volume ramp (% of run-rate) | C35: 0 | D35: 0.42 | E35: 0.85 | F35: 1 | G35: 1 | H35: 1 | I35: 1 | J35: 1 | K35: 1
B36: Savings ramp (% of run-rate) | C36: 0 | D36: 0.5 | E36: 0.9 | F36: 1 | G36: 1 | H36: 1 | I36: 1 | J36: 1 | K36: 1
B37: Equipment & long-lead ($000s) | C37: 11800 | D37: 2200 | E37: 0 | F37: 0 | G37: 0 | H37: 0 | I37: 0 | J37: 0 | K37: 0
B38: Installation / commissioning ($000s) | C38: 2800 | D38: 2800 | E38: 0 | F38: 0 | G38: 0 | H38: 0 | I38: 0 | J38: 0 | K38: 0
B39: Spares / startup ($000s) | C39: 1600 | D39: 800 | E39: 0 | F39: 0 | G39: 0 | H39: 0 | I39: 0 | J39: 0 | K39: 0
B40: Gross capex (pre-factor) | C40: =C37+C38+C39 | D40: =D37+D38+D39 | E40: =E37+E38+E39 | F40: =F37+F38+F39 | G40: =G37+G38+G39 | H40: =H37+H38+H39 | I40: =I37+I38+I39 | J40: =J37+J38+J39 | K40: =K37+K38+K39
B41: Gross capex × scenario | C41: =C40*$C$7 | D41: =D40*$C$7 | E41: =E40*$C$7 | F41: =F40*$C$7 | G41: =G40*$C$7 | H41: =H40*$C$7 | I41: =I40*$C$7 | J41: =J40*$C$7 | K41: =K40*$C$7
B42: Maintenance capex ($000s) | C42: 0 | D42: 0 | E42: 180 | F42: 180 | G42: 190 | H42: 190 | I42: 200 | J42: 200 | K42: 210
B43: Volume (000 cases) | C43: =$C$47*C35*$C$8 | D43: =$C$47*D35*$C$8 | E43: =$C$47*E35*$C$8 | F43: =$C$47*F35*$C$8 | G43: =$C$47*G35*$C$8 | H43: =$C$47*H35*$C$8 | I43: =$C$47*I35*$C$8 | J43: =$C$47*J35*$C$8 | K43: =$C$47*K35*$C$8
B44: Incremental G&A ($000s) | C44: =IF(C34>=1,$C$30,0) | D44: =IF(D34>=1,$C$30,0) | E44: =IF(E34>=1,$C$30,0) | F44: =IF(F34>=1,$C$30,0) | G44: =IF(G34>=1,$C$30,0) | H44: =IF(H34>=1,$C$30,0) | I44: =IF(I34>=1,$C$30,0) | J44: =IF(J34>=1,$C$30,0) | K44: =IF(K34>=1,$C$30,0)
B46: Unit economics and run-rate savings
B47: Run-rate volume lift (000 cases / year) | C47: 1500 | D47: Incremental cases vs doing nothing. Sample ~Line 4 nameplate after ramp.
B48: Incremental net ASP ($ / case) | C48: 11.75
...

Sheet 02_Cash_Flows
B2: Unlevered project cash flows
B3: All rows are formulas from 01_Assumptions. FCF = NOPAT + D&A − capex − maintenance − ΔNWC + salvage.
B5: Line | C5: 2026 | D5: 2027 | E5: 2028 | F5: 2029 | G5: 2030 | H5: 2031 | I5: 2032 | J5: 2033 | K5: 2034
B6: Time index t | C6: ='01_Assumptions'!C34 | D6: ='01_Assumptions'!D34 | E6: ='01_Assumptions'!E34 | F6: ='01_Assumptions'!F34 | G6: ='01_Assumptions'!G34 | H6: ='01_Assumptions'!H34 | I6: ='01_Assumptions'!I34 | J6: ='01_Assumptions'!J34 | K6: ='01_Assumptions'!K34
B8: Operating build
B9: Volume (000 cases) | C9: ='01_Assumptions'!C43 | D9: ='01_Assumptions'!D43 | E9: ='01_Assumptions'!E43 | F9: ='01_Assumptions'!F43 | G9: ='01_Assumptions'!G43 | H9: ='01_Assumptions'!H43 | I9: ='01_Assumptions'!I43 | J9: ='01_Assumptions'!J43 | K9: ='01_Assumptions'!K43
B10: Incremental revenue | C10: =C9*'01_Assumptions'!$C$48 | D10: =D9*'01_Assumptions'!$C$48 | E10: =E9*'01_Assumptions'!$C$48 | F10: =F9*'01_Assumptions'!$C$48 | G10: =G9*'01_Assumptions'!$C$48 | H10: =H9*'01_Assumptions'!$C$48 | I10: =I9*'01_Assumptions'!$C$48 | J10: =J9*'01_Assumptions'!$C$48 | K10: =K9*'01_Assumptions'!$C$48
B11: Incremental gross profit | C11: =C9*'01_Assumptions'!$C$49*'01_Assumptions'!$C$10 | D11: =D9*'01_Assumptions'!$C$49*'01_Assumptions'!$C$10 | E11: =E9*'01_Assumptions'!$C$49*'01_Assumptions'!$C$10 | F11: =F9*'01_Assumptions'!$C$49*'01_Assumptions'!$C$10 | G11: =G9*'01_Assumptions'!$C$49*'01_Assumptions'!$C$10 | H11: =H9*'01_Assumptions'!$C$49*'01_Assumptions'!$C$10 | I11: =I9*'01_Assumptions'!$C$49*'01_Assumptions'!$C$10 | J11: =J9*'01_Assumptions'!$C$49*'01_Assumptions'!$C$10 | K11: =K9*'01_Assumptions'!$C$49*'01_Assumptions'!$C$10
B12: Cost savings | C12: ='01_Assumptions'!$C$56*'01_Assumptions'!C36*'01_Assumptions'!$C$9 | D12: ='01_Assumptions'!$C$56*'01_Assumptions'!D36*'01_Assumptions'!$C$9 | E12: ='01_Assumptions'!$C$56*'01_Assumptions'!E36*'01_Assumptions'!$C$9 | F12: ='01_Assumptions'!$C$56*'01_Assumptions'!F36*'01_Assumptions'!$C$9 | G12: ='01_Assumptions'!$C$56*'01_Assumptions'!G36*'01_Assumptions'!$C$9 | H12: ='01_Assumptions'!$C$56*'01_Assumptions'!H36*'01_Assumptions'!$C$9 | I12: ='01_Assumptions'!$C$56*'01_Assumptions'!I36*'01_Assumptions'!$C$9 | J12: ='01_Assumptions'!$C$56*'01_Assumptions'!J36*'01_Assumptions'!$C$9 | K12: ='01_Assumptions'!$C$56*'01_Assumptions'!K36*'01_Assumptions'!$C$9
B13: Variable distribution | C13: =C9*'01_Assumptions'!$C$50 | D13: =D9*'01_Assumptions'!$C$50 | E13: =E9*'01_Assumptions'!$C$50 | F13: =F9*'01_Assumptions'!$C$50 | G13: =G9*'01_Assumptions'!$C$50 | H13: =H9*'01_Assumptions'!$C$50 | I13: =I9*'01_Assumptions'!$C$50 | J13: =J9*'01_Assumptions'!$C$50 | K13: =K9*'01_Assumptions'!$C$50
B14: Incremental G&A | C14: ='01_Assumptions'!C44 | D14: ='01_Assumptions'!D44 | E14: ='01_Assumptions'!E44 | F14: ='01_Assumptions'!F44 | G14: ='01_Assumptions'!G44 | H14: ='01_Assumptions'!H44 | I14: ='01_Assumptions'!I44 | J14: ='01_Assumptions'!J44 | K14: ='01_Assumptions'!K44
B15: Incremental EBITDA | C15: =C11+C12-C13-C14 | D15: =D11+D12-D13-D14 | E15: =E11+E12-E13-E14 | F15: =F11+F12-F13-F14 | G15: =G11+G12-G13-G14 | H15: =H11+H12-H13-H14 | I15: =I11+I12-I13-I14 | J15: =J11+J12-J13-J14 | K15: =K11+K12-K13-K14
B16: D&A | C16: =IF(AND(C6>=1,C6<='01_Assumptions'!$C$27),'01_Assumptions'!$C$62,0) | D16: =IF(AND(D6>=1,D6<='01_Assumptions'!$C$27),'01_Assumptions'!$C$62,0) | E16: =IF(AND(E6>=1,E6<='01_Assumptions'!$C$27),'01_Assumptions'!$C$62,0) | F16: =IF(AND(F6>=1,F6<='01_Assumptions'!$C$27),'01_Assumptions'!$C$62,0) | G16: =IF(AND(G6>=1,G6<='01_Assumptions'!$C$27),'01_Assumptions'!$C$62,0) | H16: =IF(AND(H6>=1,H6<='01_Assumptions'!$C$27),'01_Assumptions'!$C$62,0) | I16: =IF(AND(I6>=1,I6<='01_Assumptions'!$C$27),'01_Assumptions'!$C$62,0) | J16: =IF(AND(J6>=1,J6<='01_Assumptions'!$C$27),'01_Assumptions'!$C$62,0) | K16: =IF(AND(K6>=1,K6<='01_Assumptions'!$C$27),'01_Assumptions'!$C$62,0)
B17: EBIT | C17: =C15-C16 | D17: =D15-D16 | E17: =E15-E16 | F17: =F15-F16 | G17: =G15-G16 | H17: =H15-H16 | I17: =I15-I16 | J17: =J15-J16 | K17: =K15-K16
B18: Tax on EBIT | C18: =C17*'01_Assumptions'!$C$26 | D18: =D17*'01_Assumptions'!$C$26 | E18: =E17*'01_Assumptions'!$C$26 | F18: =F17*'01_Assumptions'!$C$26 | G18: =G17*'01_Assumptions'!$C$26 | H18: =H17*'01_Assumptions'!$C$26 | I18: =I17*'01_Assumptions'!$C$26 | J18: =J17*'01_Assumptions'!$C$26 | K18: =K17*'01_Assumptions'!$C$26
B19: NOPAT | C19: =C17-C18 | D19: =D17-D18 | E19: =E17-E18 | F19: =F17-F18 | G19: =G17-G18 | H19: =H17-H18 | I19: =I17-I18 | J19: =J17-J18 | K19: =K17-K18
B20: + D&A | C20: =C16 | D20: =D16 | E20: =E16 | F20: =F16 | G20: =G16 | H20: =H16 | I20: =I16 | J20: =J16 | K20: =K16
B21: Gross cash flow | C21: =C19+C20 | D21: =D19+D20 | E21: =E19+E20 | F21: =F19+F20 | G21: =G19+G20 | H21: =H19+H20 | I21: =I19+I20 | J21: =J19+J20 | K21: =K19+K20
B23: Investment
B24: Gross capex (spend) | C24: ='01_Assumptions'!C41 | D24: ='01_Assumptions'!D41 | E24: ='01_Assumptions'!E41 | F24: ='01_Assumptions'!F41 | G24: ='01_Assumptions'!G41 | H24: ='01_Assumptions'!H41 | I24: ='01_Assumptions'!I41 | J24: ='01_Assumptions'!J41 | K24: ='01_Assumptions'!K41
B25: Maintenance capex | C25: ='01_Assumptions'!C42 | D25: ='01_Assumptions'!D42 | E25: ='01_Assumptions'!E42 | F25: ='01_Assumptions'!F42 | G25: ='01_Assumptions'!G42 | H25: ='01_Assumptions'!H42 | I25: ='01_Assumptions'!I42 | J25: ='01_Assumptions'!J42 | K25: ='01_Assumptions'!K42
B26: NWC balance | C26: =IF(C6>='01_Assumptions'!$C$27,0,'01_Assumptions'!$C$29*C10) | D26: =IF(D6>='01_Assumptions'!$C$27,0,'01_Assumptions'!$C$29*D10) | E26: =IF(E6>='01_Assumptions'!$C$27,0,'01_Assumptions'!$C$29*E10) | F26: =IF(F6>='01_Assumptions'!$C$27,0,'01_Assumptions'!$C$29*F10) | G26: =IF(G6>='01_Assumptions'!$C$27,0,'01_Assumptions'!$C$29*G10) | H26: =IF(H6>='01_Assumptions'!$C$27,0,'01_Assumptions'!$C$29*H10) | I26: =IF(I6>='01_Assumptions'!$C$27,0,'01_Assumptions'!$C$29*I10) | J26: =IF(J6>='01_Assumptions'!$C$27,0,'01_Assumptions'!$C$29*J10) | K26: =IF(K6>='01_Assumptions'!$C$27,0,'01_Assumptions'!$C$29*K10)
B27: Δ NWC (use of cash) | C27: =C26 | D27: =D26-C26 | E27: =E26-D26 | F27: =F26-E26 | G27: =G26-F26 | H27: =H26-G26 | I27: =I26-H26 | J27: =J26-I26 | K27: =K26-J26
B28: After-tax salvage | C28: =IF(C6='01_Assumptions'!$C$27,'01_Assumptions'!$C$60,0) | D28: =IF(D6='01_Assumptions'!$C$27,'01_Assumptions'!$C$60,0) | E28: =IF(E6='01_Assumptions'!$C$27,'01_Assumptions'!$C$60,0) | F28: =IF(F6='01_Assumptions'!$C$27,'01_Assumptions'!$C$60,0) | G28: =IF(G6='01_Assumptions'!$C$27,'01_Assumptions'!$C$60,0) | H28: =IF(H6='01_Assumptions'!$C$27,'01_Assumptions'!$C$60,0) | I28: =IF(I6='01_Assumptions'!$C$27,'01_Assumptions'!$C$60,0) | J28: =IF(J6='01_Assumptions'!$C$27,'01_Assumptions'!$C$60,0) | K28: =IF(K6='01_Assumptions'!$C$27,'01_Assumptions'!$C$60,0)
B29: Unlevered FCF | C29: =C21-C24-C25-C27+C28 | D29: =D21-D24-D25-D27+D28 | E29: =E21-E24-E25-E27+E28 | F29: =F21-F24-F25-F27+F28 | G29: =G21-G24-G25-G27+G28 | H29: =H21-H24-H25-H27+H28 | I29: =I21-I24-I25-I27+I28 | J29: =J21-J24-J25-J27+J28 | K29: =K21-K24-K25-K27+K28
B30: Cumulative FCF | C30: =C29 | D30: =C30+D29 | E30: =D30+E29 | F30: =E30+F29 | G30: =F30+G29 | H30: =G30+H29 | I30: =H30+I29 | J30: =I30+J29 | K30: =J30+K29
B32: Discounting
B33: Discount factor | C33: =1/(1+'01_Assumptions'!$C$25)^C6 | D33: =1/(1+'01_Assumptions'!$C$25)^D6 | E33: =1/(1+'01_Assumptions'!$C$25)^E6 | F33: =1/(1+'01_Assumptions'!$C$25)^F6 | G33: =1/(1+'01_Assumptions'!$C$25)^G6 | H33: =1/(1+'01_Assumptions'!$C$25)^H6 | I33: =1/(1+'01_Assumptions'!$C$25)^I6 | J33: =1/(1+'01_Assumptions'!$C$25)^J6 | K33: =1/(1+'01_Assumptions'!$C$25)^K6
B34: PV of FCF | C34: =C29*C33 | D34: =D29*D33 | E34: =E29*E33 | F34: =F29*F33 | G34: =G29*G33 | H34: =H29*H33 | I34: =I29*I33 | J34: =J29*J33 | K34: =K29*K33
B35: Cumulative PV of FCF | C35: =C34 | D35: =C35+D34 | E35: =D35+E34 | F35: =E35+F34 | G35: =F35+G34 | H35: =G35+H34 | I35: =H35+I34 | J35: =I35+J34 | K35: =J35+K34
B37: NWC is released in the final project year (balance set to 0). Salvage equals the residual book value, so it is untaxed. Tax on EBIT can be negative in the install year (tax shield).

Sheet 03_Returns
B2: Returns
B3: NPV at WACC, IRR, payback (undiscounted and discounted), profitability index. All formulas from 02_Cash_Flows.
B5: Investment committee metrics
B6: NPV ($000s) | C6: =NPV('01_Assumptions'!C25,'02_Cash_Flows'!D29:K29)+'02_Cash_Flows'!C29 | D6: Year-end discounting. NPV = FCF₀ + NPV(WACC, FCF₁…FCF₈).
B7: IRR | C7: =IRR('02_Cash_Flows'!C29:K29) | D7: IRR on the unlevered FCF series including t = 0 spend.
B8: WACC (hurdle) | C8: ='01_Assumptions'!C25
B9: IRR − WACC (spread) | C9: =C7-C8
B10: Total gross capex ($000s) | C10: ='01_Assumptions'!C59
B11: PV of capex + maintenance ($000s) | C11: =SUMPRODUCT('02_Cash_Flows'!C24:K24+'02_Cash_Flows'!C25:K25,'02_Cash_Flows'!C33:K33)
B12: Profitability index | C12: =IF(C11=0,"n.m.",(C6+C11)/C11) | D12: (NPV + PV of investment) / PV of investment. >1 with NPV > 0.
B13: Undiscounted payback (years from 2026) | C13: =C42
B14: Discounted payback (years from 2026) | C14: =C48
B15: Sum of unlevered FCF ($000s) | C15: =SUM('02_Cash_Flows'!C29:K29)
B17: Recommendation
B18: Decision | C18: =IF(AND(ISNUMBER(C6),C6>0,ISNUMBER(C7),C7>C8,ISNUMBER(C13),C13<=5),"Recommend approve","Review — NPV, spread, or payback off-hurdle")
B19: Rule | C19: Approve if NPV > 0, IRR > WACC, and undiscounted payback ≤ 5 years. Otherwise review.
B21: Cash-flow strip (for payback and chart)
B22: Item | C22: 2026 | D22: 2027 | E22: 2028 | F22: 2029 | G22: 2030 | H22: 2031 | I22: 2032 | J22: 2033 | K22: 2034
B23: t | C23: ='02_Cash_Flows'!C6 | D23: ='02_Cash_Flows'!D6 | E23: ='02_Cash_Flows'!E6 | F23: ='02_Cash_Flows'!F6 | G23: ='02_Cash_Flows'!G6 | H23: ='02_Cash_Flows'!H6 | I23: ='02_Cash_Flows'!I6 | J23: ='02_Cash_Flows'!J6 | K23: ='02_Cash_Flows'!K6
B24: Unlevered FCF | C24: ='02_Cash_Flows'!C29 | D24: ='02_Cash_Flows'!D29 | E24: ='02_Cash_Flows'!E29 | F24: ='02_Cash_Flows'!F29 | G24: ='02_Cash_Flows'!G29 | H24: ='02_Cash_Flows'!H29 | I24: ='02_Cash_Flows'!I29 | J24: ='02_Cash_Flows'!J29 | K24: ='02_Cash_Flows'!K29
B25: Cumulative FCF | C25: ='02_Cash_Flows'!C30 | D25: ='02_Cash_Flows'!D30 | E25: ='02_Cash_Flows'!E30 | F25: ='02_Cash_Flows'!F30 | G25: ='02_Cash_Flows'!G30 | H25: ='02_Cash_Flows'!H30 | I25: ='02_Cash_Flows'!I30 | J25: ='02_Cash_Flows'!J30 | K25: ='02_Cash_Flows'!K30
B26: PV of FCF | C26: ='02_Cash_Flows'!C34 | D26: ='02_Cash_Flows'!D34 | E26: ='02_Cash_Flows'!E34 | F26: ='02_Cash_Flows'!F34 | G26: ='02_Cash_Flows'!G34 | H26: ='02_Cash_Flows'!H34 | I26: ='02_Cash_Flows'!I34 | J26: ='02_Cash_Flows'!J34 | K26: ='02_Cash_Flows'!K34
B27: Cumulative PV | C27: ='02_Cash_Flows'!C35 | D27: ='02_Cash_Flows'!D35 | E27: ='02_Cash_Flows'!E35 | F27: ='02_Cash_Flows'!F35 | G27: ='02_Cash_Flows'!G35 | H27: ='02_Cash_Flows'!H35 | I27: ='02_Cash_Flows'!I35 | J27: ='02_Cash_Flows'!J35 | K27: ='02_Cash_Flows'!K35
B28: Payback crossing (undiscounted) | C28: =IF(C25>=0,0,0) | D28: =IF(AND(C25<0,D25>=0),C23+ABS(C25)/D24,0) | E28: =IF(AND(D25<0,E25>=0),D23+ABS(D25)/E24,0) | F28: =IF(AND(E25<0,F25>=0),E23+ABS(E25)/F24,0) | G28: =IF(AND(F25<0,G25>=0),F23+ABS(F25)/G24,0) | H28: =IF(AND(G25<0,H25>=0),G23+ABS(G25)/H24,0) | I28: =IF(AND(H25<0,I25>=0),H23+ABS(H25)/I24,0) | J28: =IF(AND(I25<0,J25>=0),I23+ABS(I25)/J24,0) | K28: =IF(AND(J25<0,K25>=0),J23+ABS(J25)/K24,0)
B29: Payback crossing (discounted) | C29: =IF(C27>=0,0,0) | D29: =IF(AND(C27<0,D27>=0),C23+ABS(C27)/D26,0) | E29: =IF(AND(D27<0,E27>=0),D23+ABS(D27)/E26,0) | F29: =IF(AND(E27<0,F27>=0),E23+ABS(E27)/F26,0) | G29: =IF(AND(F27<0,G27>=0),F23+ABS(F27)/G26,0) | H29: =IF(AND(G27<0,H27>=0),G23+ABS(G27)/H26,0) | I29: =IF(AND(H27<0,I27>=0),H23+ABS(H27)/I26,0) | J29: =IF(AND(I27<0,J27>=0),I23+ABS(I27)/J26,0) | K29: =IF(AND(J27<0,K27>=0),J23+ABS(J27)/K26,0)
B31: Payback helpers
B32: First year cumulative FCF ≥ 0 (t) | C32: =IF(COUNTIF(C25:K25,">=0")=0,"n.m.",INDEX(C23:K23,1,MATCH(TRUE,INDEX(C25:K25>=0,0),0)))
B33: Crossing flag sum (undiscounted) | C33: =SUM(C28:K28)
B34: Crossing flag sum (discounted) | C34: =SUM(C29:K29)
B36: Undiscounted payback (years) | C36: =IF(K25<0,NA(),IF(C25>=0,0,C33))
B37: Discounted payback (years) | C37: =IF(K27<0,NA(),IF(C27>=0,0,C34))
B39: Annual unlevered FCF and cumulative ($000s)
B42: (alias for C13) | C42: =C36
B48: (alias for C14) | C48: =C37
B82: Payback is interpolated in the crossing year: t_prior + |cumulative_prior| / FCF_crossing. n.m. if cumulative never turns positive.

Sheet 04_Sensitivity
B2: Sensitivity
B3: WACC one-way uses the live FCF strip. Volume two-way rebuilds FCF (volume-driven lines × factor; savings, capex, G&A, D&A held at the current case).
B5: Base case (current scenario)
B6: NPV | C6: ='03_Returns'!C6
B7: IRR | C7: ='03_Returns'!C7
B8: WACC | C8: ='01_Assumptions'!C25
B10: One-way — NPV vs WACC (live FCF strip)
B11: WACC | C11: NPV ($000s) | D11: vs base
B12: 0.07 | C12: =NPV(B12,'02_Cash_Flows'!D29:K29)+'02_Cash_Flows'!C29 | D12: =C12-$C$6
B13: 0.08 | C13: =NPV(B13,'02_Cash_Flows'!D29:K29)+'02_Cash_Flows'!C29 | D13: =C13-$C$6
B14: 0.095 | C14: =NPV(B14,'02_Cash_Flows'!D29:K29)+'02_Cash_Flows'!C29 | D14: =C14-$C$6
B15: 0.11 | C15: =NPV(B15,'02_Cash_Flows'!D29:K29)+'02_Cash_Flows'!C29 | D15: =C15-$C$6
B16: 0.125 | C16: =NPV(B16,'02_Cash_Flows'!D29:K29)+'02_Cash_Flows'!C29 | D16: =C16-$C$6
B19: Two-way engine — FCF by volume factor (current case = 100%)
B20: Volume factor \ Year | C20: 2026 | D20: 2027 | E20: 2028 | F20: 2029 | G20: 2030 | H20: 2031 | I20: 2032 | J20: 2033 | K20: 2034
B21: 0.8 | C21: =($B21*'02_Cash_Flows'!C11+'02_Cash_Flows'!C12-$B21*'02_Cash_Flows'!C13-'02_Cash_Flows'!C14-'02_Cash_Flows'!C16)*(1-'01_Assumptions'!$C$26)+'02_Cash_Flows'!C16-'02_Cash_Flows'!C24-'02_Cash_Flows'!C25-(IF('02_Cash_Flows'!C6>='01_Assumptions'!$C$27,0,'01_Assumptions'!$C$29*$B21*'02_Cash_Flows'!C10))+'02_Cash_Flows'!C28 | D21: =($B21*'02_Cash_Flows'!D11+'02_Cash_Flows'!D12-$B21*'02_Cash_Flows'!D13-'02_Cash_Flows'!D14-'02_Cash_Flows'!D16)*(1-'01_Assumptions'!$C$26)+'02_Cash_Flows'!D16-'02_Cash_Flows'!D24-'02_Cash_Flows'!D25-((IF('02_Cash_Flows'!D6>='01_Assumptions'!$C$27,0,'01_Assumptions'!$C$29*$B21*'02_Cash_Flows'!D10))-(IF('02_Cash_Flows'!C6>='01_Assumptions'!$C$27,0,'01_Assumptions'!$C$29*$B21*'02_Cash_Flows'!C10)))+'02_Cash_Flows'!D28 | E21: =($B21*'02_Cash_Flows'!E11+'02_Cash_Flows'!E12-$B21*'02_Cash_Flows'!E13-'02_Cash_Flows'!E14-'02_Cash_Flows'!E16)*(1-'01_Assumptions'!$C$26)+'02_Cash_Flows'!E16-'02_Cash_Flows'!E24-'02_Cash_Flows'!E25-((IF('02_Cash_Flows'!E6>='01_Assumptions'!$C$27,0,'01_Assumptions'!$C$29*$B21*'02_Cash_Flows'!E10))-(IF('02_Cash_Flows'!D6>='01_Assumptions'!$C$27,0,'01_Assumptions'!$C$29*$B21*'02_Cash_Flows'!D10)))+'02_Cash_Flows'!E28 | F21: =($B21*'02_Cash_Flows'!F11+'02_Cash_Flows'!F12-$B21*'02_Cash_Flows'!F13-'02_Cash_Flows'!F14-'02_Cash_Flows'!F16)*(1-'01_Assumptions'!$C$26)+'02_Cash_Flows'!F16-'02_Cash_Flows'!F24-'02_Cash_Flows'!F25-((IF('02_Cash_Flows'!F6>='01_Assumptions'!$C$27,0,'01_Assumptions'!$C$29*$B21*'02_Cash_Flows'!F10))-(IF('02_Cash_Flows'!E6>='01_Assumptions'!$C$27,0,'01_Assumptions'!$C$29*$B21*'02_Cash_Flows'!E10)))+'02_Cash_Flows'!F28 | G21: =($B21*'02_Cash_Flows'!G11+'02_Cash_Flows'!G12-$B21*'02_Cash_Flows'!G13-'02_Cash_Flows'!G14-'02_Cash_Flows'!G16)*(1-'01_Assumptions'!$C$26)+'02_Cash_Flows'!G16-'02_Cash_Flows'!G24-'02_Cash_Flows'!G25-((IF('02_Cash_Flows'!G6>='01_Assumptions'!$C$27,0,'01_Assumptions'!$C$29*$B21*'02_Cash_Flows'!G10))-(IF('02_Cash_Flows'!F6>='01_Assumptions'!$C$27,0,'01_Assumptions'!$C$29*$B21*'02_Cash_Flows'!F10)))+'02_Cash_Flows'!G28 | H21: =($B21*'02_Cash_Flows'!H11+'02_Cash_Flows'!H12-$B21*'02_Cash_Flows'!H13-'02_Cash_Flows'!H14-'02_Cash_Flows'!H16)*(1-'01_Assumptions'!$C$26)+'02_Cash_Flows'!H16-'02_Cash_Flows'!H24-'02_Cash_Flows'!H25-((IF('02_Cash_Flows'!H6>='01_Assumptions'!$C$27,0,'01_Assumptions'!$C$29*$B21*'02_Cash_Flows'!H10))-(IF('02_Cash_Flows'!G6>='01_Assumptions'!$C$27,0,'01_Assumptions'!$C$29*$B21*'02_Cash_Flows'!G10)))+'02_Cash_Flows'!H28 | I21: =($B21*'02_Cash_Flows'!I11+'02_Cash_Flows'!I12-$B21*'02_Cash_Flows'!I13-'02_Cash_Flows'!I14-'02_Cash_Flows'!I16)*(1-'01_Assumptions'!$C$26)+'02_Cash_Flows'!I16-'02_Cash_Flows'!I24-'02_Cash_Flows'!I25-((IF('02_Cash_Flows'!I6>='01_Assumptions'!$C$27,0,'01_Assumptions'!$C$29*$B21*'02_Cash_Flows'!I10))-(IF('02_Cash_Flows'!H6>='01_Assumptions'!$C$27,0,'01_Assumptions'!$C$29*$B21*'02_Cash_Flows'!H10)))+'02_Cash_Flows'!I28 | J21: =($B21*'02_Cash_Flows'!J11+'02_Cash_Flows'!J12-$B21*'02_Cash_Flows'!J13-'02_Cash_Flows'!J14-'02_Cash_Flows'!J16)*(1-'01_Assumptions'!$C$26)+'02_Cash_Flows'!J16-'02_Cash_Flows'!J24-'02_Cash_Flows'!J25-((IF('02_Cash_Flows'!J6>='01_Assumptions'!$C$27,0,'01_Assumptions'!$C$29*$B21*'02_Cash_Flows'!J10))-(IF('02_Cash_Flows'!I6>='01_Assumptions'!$C$27,0,'01_Assumptions'!$C$29*$B21*'02_Cash_Flows'!I10)))+'02_Cash_Flows'!J28 | K21: =($B21*'02_Cash_Flows'!K11+'02_Cash_Flows'!K12-$B21*'02_Cash_Flows'!K13-'02_Cash_Flows'!K14-'02_Cash_Flows'!K16)*(1-'01_Assumptions'!$C$26)+'02_Cash_Flows'!K16-'02_Cash_Flows'!K24-'02_Cash_Flows'!K25-((IF('02_Cash_Flows'!K6>='01_Assumptions'!$C$27,0,'01_Assumptions'!$C$29*$B21*'02_Cash_Flows'!K10))-(IF('02_Cash_Flows'!J6>='01_Assumptions'!$C$27,0,'01_Assumptions'!$C$29*$B21*'02_Cash_Flows'!J10)))+'02_Cash_Flows'!K28
B22: 0.9 | C22: =($B22*'02_Cash_Flows'!C11+'02_Cash_Flows'!C12-$B22*'02_Cash_Flows'!C13-'02_Cash_Flows'!C14-'02_Cash_Flows'!C16)*(1-'01_Assumptions'!$C$26)+'02_Cash_Flows'!C16-'02_Cash_Flows'!C24-'02_Cash_Flows'!C25-(IF('02_Cash_Flows'!C6>='01_Assumptions'!$C$27,0,'01_Assumptions'!$C$29*$B22*'02_Cash_Flows'!C10))+'02_Cash_Flows'!C28 | D22: =($B22*'02_Cash_Flows'!D11+'02_Cash_Flows'!D12-$B22*'02_Cash_Flows'!D13-'02_Cash_Flows'!D14-'02_Cash_Flows'!D16)*(1-'01_Assumptions'!$C$26)+'02_Cash_Flows'!D16-'02_Cash_Flows'!D24-'02_Cash_Flows'!D25-((IF('02_Cash_Flows'!D6>='01_Assumptions'!$C$27,0,'01_Assumptions'!$C$29*$B22*'02_Cash_Flows'!D10))-(IF('02_Cash_Flows'!C6>='01_Assumptions'!$C$27,0,'01_Assumptions'!$C$29*$B22*'02_Cash_Flows'!C10)))+'02_Cash_Flows'!D28 | E22: =($B22*'02_Cash_Flows'!E11+'02_Cash_Flows'!E12-$B22*'02_Cash_Flows'!E13-'02_Cash_Flows'!E14-'02_Cash_Flows'!E16)*(1-'01_Assumptions'!$C$26)+'02_Cash_Flows'!E16-'02_Cash_Flows'!E24-'02_Cash_Flows'!E25-((IF('02_Cash_Flows'!E6>='01_Assumptions'!$C$27,0,'01_Assumptions'!$C$29*$B22*'02_Cash_Flows'!E10))-(IF('02_Cash_Flows'!D6>='01_Assumptions'!$C$27,0,'01_Assumptions'!$C$29*$B22*'02_Cash_Flows'!D10)))+'02_Cash_Flows'!E28 | F22: =($B22*'02_Cash_Flows'!F11+'02_Cash_Flows'!F12-$B22*'02_Cash_Flows'!F13-'02_Cash_Flows'!F14-'02_Cash_Flows'!F16)*(1-'01_Assumptions'!$C$26)+'02_Cash_Flows'!F16-'02_Cash_Flows'!F24-'02_Cash_Flows'!F25-((IF('02_Cash_Flows'!F6>='01_Assumptions'!$C$27,0,'01_Assumptions'!$C$29*$B22*'02_Cash_Flows'!F10))-(IF('02_Cash_Flows'!E6>='01_Assumptions'!$C$27,0,'01_Assumptions'!$C$29*$B22*'02_Cash_Flows'!E10)))+'02_Cash_Flows'!F28 | G22: =($B22*'02_Cash_Flows'!G11+'02_Cash_Flows'!G12-$B22*'02_Cash_Flows'!G13-'02_Cash_Flows'!G14-'02_Cash_Flows'!G16)*(1-'01_Assumptions'!$C$26)+'02_Cash_Flows'!G16-'02_Cash_Flows'!G24-'02_Cash_Flows'!G25-((IF('02_Cash_Flows'!G6>='01_Assumptions'!$C$27,0,'01_Assumptions'!$C$29*$B22*'02_Cash_Flows'!G10))-(IF('02_Cash_Flows'!F6>='01_Assumptions'!$C$27,0,'01_Assumptions'!$C$29*$B22*'02_Cash_Flows'!F10)))+'02_Cash_Flows'!G28 | H22: =($B22*'02_Cash_Flows'!H11+'02_Cash_Flows'!H12-$B22*'02_Cash_Flows'!H13-'02_Cash_Flows'!H14-'02_Cash_Flows'!H16)*(1-'01_Assumptions'!$C$26)+'02_Cash_Flows'!H16-'02_Cash_Flows'!H24-'02_Cash_Flows'!H25-((IF('02_Cash_Flows'!H6>='01_Assumptions'!$C$27,0,'01_Assumptions'!$C$29*$B22*'02_Cash_Flows'!H10))-(IF('02_Cash_Flows'!G6>='01_Assumptions'!$C$27,0,'01_Assumptions'!$C$29*$B22*'02_Cash_Flows'!G10)))+'02_Cash_Flows'!H28 | I22: =($B22*'02_Cash_Flows'!I11+'02_Cash_Flows'!I12-$B22*'02_Cash_Flows'!I13-'02_Cash_Flows'!I14-'02_Cash_Flows'!I16)*(1-'01_Assumptions'!$C$26)+'02_Cash_Flows'!I16-'02_Cash_Flows'!I24-'02_Cash_Flows'!I25-((IF('02_Cash_Flows'!I6>='01_Assumptions'!$C$27,0,'01_Assumptions'!$C$29*$B22*'02_Cash_Flows'!I10))-(IF('02_Cash_Flows'!H6>='01_Assumptions'!$C$27,0,'01_Assumptions'!$C$29*$B22*'02_Cash_Flows'!H10)))+'02_Cash_Flows'!I28 | J22: =($B22*'02_Cash_Flows'!J11+'02_Cash_Flows'!J12-$B22*'02_Cash_Flows'!J13-'02_Cash_Flows'!J14-'02_Cash_Flows'!J16)*(1-'01_Assumptions'!$C$26)+'02_Cash_Flows'!J16-'02_Cash_Flows'!J24-'02_Cash_Flows'!J25-((IF('02_Cash_Flows'!J6>='01_Assumptions'!$C$27,0,'01_Assumptions'!$C$29*$B22*'02_Cash_Flows'!J10))-(IF('02_Cash_Flows'!I6>='01_Assumptions'!$C$27,0,'01_Assumptions'!$C$29*$B22*'02_Cash_Flows'!I10)))+'02_Cash_Flows'!J28 | K22: =($B22*'02_Cash_Flows'!K11+'02_Cash_Flows'!K12-$B22*'02_Cash_Flows'!K13-'02_Cash_Flows'!K14-'02_Cash_Flows'!K16)*(1-'01_Assumptions'!$C$26)+'02_Cash_Flows'!K16-'02_Cash_Flows'!K24-'02_Cash_Flows'!K25-((IF('02_Cash_Flows'!K6>='01_Assumptions'!$C$27,0,'01_Assumptions'!$C$29*$B22*'02_Cash_Flows'!K10))-(IF('02_Cash_Flows'!J6>='01_Assumptions'!$C$27,0,'01_Assumptions'!$C$29*$B22*'02_Cash_Flows'!J10)))+'02_Cash_Flows'!K28
B23: 1 | C23: =($B23*'02_Cash_Flows'!C11+'02_Cash_Flows'!C12-$B23*'02_Cash_Flows'!C13-'02_Cash_Flows'!C14-'02_Cash_Flows'!C16)*(1-'01_Assumptions'!$C$26)+'02_Cash_Flows'!C16-'02_Cash_Flows'!C24-'02_Cash_Flows'!C25-(IF('02_Cash_Flows'!C6>='01_Assumptions'!$C$27,0,'01_Assumptions'!$C$29*$B23*'02_Cash_Flows'!C10))+'02_Cash_Flows'!C28 | D23: =($B23*'02_Cash_Flows'!D11+'02_Cash_Flows'!D12-$B23*'02_Cash_Flows'!D13-'02_Cash_Flows'!D14-'02_Cash_Flows'!D16)*(1-'01_Assumptions'!$C$26)+'02_Cash_Flows'!D16-'02_Cash_Flows'!D24-'02_Cash_Flows'!D25-((IF('02_Cash_Flows'!D6>='01_Assumptions'!$C$27,0,'01_Assumptions'!$C$29*$B23*'02_Cash_Flows'!D10))-(IF('02_Cash_Flows'!C6>='01_Assumptions'!$C$27,0,'01_Assumptions'!$C$29*$B23*'02_Cash_Flows'!C10)))+'02_Cash_Flows'!D28 | E23: =($B23*'02_Cash_Flows'!E11+'02_Cash_Flows'!E12-$B23*'02_Cash_Flows'!E13-'02_Cash_Flows'!E14-'02_Cash_Flows'!E16)*(1-'01_Assumptions'!$C$26)+'02_Cash_Flows'!E16-'02_Cash_Flows'!E24-'02_Cash_Flows'!E25-((IF('02_Cash_Flows'!E6>='01_Assumptions'!$C$27,0,'01_Assumptions'!$C$29*$B23*'02_Cash_Flows'!E10))-(IF('02_Cash_Flows'!D6>='01_Assumptions'!$C$27,0,'01_Assumptions'!$C$29*$B23*'02_Cash_Flows'!D10)))+'02_Cash_Flows'!E28 | F23: =($B23*'02_Cash_Flows'!F11+'02_Cash_Flows'!F12-$B23*'02_Cash_Flows'!F13-'02_Cash_Flows'!F14-'02_Cash_Flows'!F16)*(1-'01_Assumptions'!$C$26)+'02_Cash_Flows'!F16-'02_Cash_Flows'!F24-'02_Cash_Flows'!F25-((IF('02_Cash_Flows'!F6>='01_Assumptions'!$C$27,0,'01_Assumptions'!$C$29*$B23*'02_Cash_Flows'!F10))-(IF('02_Cash_Flows'!E6>='01_Assumptions'!$C$27,0,'01_Assumptions'!$C$29*$B23*'02_Cash_Flows'!E10)))+'02_Cash_Flows'!F28 | G23: =($B23*'02_Cash_Flows'!G11+'02_Cash_Flows'!G12-$B23*'02_Cash_Flows'!G13-'02_Cash_Flows'!G14-'02_Cash_Flows'!G16)*(1-'01_Assumptions'!$C$26)+'02_Cash_Flows'!G16-'02_Cash_Flows'!G24-'02_Cash_Flows'!G25-((IF('02_Cash_Flows'!G6>='01_Assumptions'!$C$27,0,'01_Assumptions'!$C$29*$B23*'02_Cash_Flows'!G10))-(IF('02_Cash_Flows'!F6>='01_Assumptions'!$C$27,0,'01_Assumptions'!$C$29*$B23*'02_Cash_Flows'!F10)))+'02_Cash_Flows'!G28 | H23: =($B23*'02_Cash_Flows'!H11+'02_Cash_Flows'!H12-$B23*'02_Cash_Flows'!H13-'02_Cash_Flows'!H14-'02_Cash_Flows'!H16)*(1-'01_Assumptions'!$C$26)+'02_Cash_Flows'!H16-'02_Cash_Flows'!H24-'02_Cash_Flows'!H25-((IF('02_Cash_Flows'!H6>='01_Assumptions'!$C$27,0,'01_Assumptions'!$C$29*$B23*'02_Cash_Flows'!H10))-(IF('02_Cash_Flows'!G6>='01_Assumptions'!$C$27,0,'01_Assumptions'!$C$29*$B23*'02_Cash_Flows'!G10)))+'02_Cash_Flows'!H28 | I23: =($B23*'02_Cash_Flows'!I11+'02_Cash_Flows'!I12-$B23*'02_Cash_Flows'!I13-'02_Cash_Flows'!I14-'02_Cash_Flows'!I16)*(1-'01_Assumptions'!$C$26)+'02_Cash_Flows'!I16-'02_Cash_Flows'!I24-'02_Cash_Flows'!I25-((IF('02_Cash_Flows'!I6>='01_Assumptions'!$C$27,0,'01_Assumptions'!$C$29*$B23*'02_Cash_Flows'!I10))-(IF('02_Cash_Flows'!H6>='01_Assumptions'!$C$27,0,'01_Assumptions'!$C$29*$B23*'02_Cash_Flows'!H10)))+'02_Cash_Flows'!I28 | J23: =($B23*'02_Cash_Flows'!J11+'02_Cash_Flows'!J12-$B23*'02_Cash_Flows'!J13-'02_Cash_Flows'!J14-'02_Cash_Flows'!J16)*(1-'01_Assumptions'!$C$26)+'02_Cash_Flows'!J16-'02_Cash_Flows'!J24-'02_Cash_Flows'!J25-((IF('02_Cash_Flows'!J6>='01_Assumptions'!$C$27,0,'01_Assumptions'!$C$29*$B23*'02_Cash_Flows'!J10))-(IF('02_Cash_Flows'!I6>='01_Assumptions'!$C$27,0,'01_Assumptions'!$C$29*$B23*'02_Cash_Flows'!I10)))+'02_Cash_Flows'!J28 | K23: =($B23*'02_Cash_Flows'!K11+'02_Cash_Flows'!K12-$B23*'02_Cash_Flows'!K13-'02_Cash_Flows'!K14-'02_Cash_Flows'!K16)*(1-'01_Assumptions'!$C$26)+'02_Cash_Flows'!K16-'02_Cash_Flows'!K24-'02_Cash_Flows'!K25-((IF('02_Cash_Flows'!K6>='01_Assumptions'!$C$27,0,'01_Assumptions'!$C$29*$B23*'02_Cash_Flows'!K10))-(IF('02_Cash_Flows'!J6>='01_Assumptions'!$C$27,0,'01_Assumptions'!$C$29*$B23*'02_Cash_Flows'!J10)))+'02_Cash_Flows'!K28
B24: 1.1 | C24: =($B24*'02_Cash_Flows'!C11+'02_Cash_Flows'!C12-$B24*'02_Cash_Flows'!C13-'02_Cash_Flows'!C14-'02_Cash_Flows'!C16)*(1-'01_Assumptions'!$C$26)+'02_Cash_Flows'!C16-'02_Cash_Flows'!C24-'02_Cash_Flows'!C25-(IF('02_Cash_Flows'!C6>='01_Assumptions'!$C$27,0,'01_Assumptions'!$C$29*$B24*'02_Cash_Flows'!C10))+'02_Cash_Flows'!C28 | D24: =($B24*'02_Cash_Flows'!D11+'02_Cash_Flows'!D12-$B24*'02_Cash_Flows'!D13-'02_Cash_Flows'!D14-'02_Cash_Flows'!D16)*(1-'01_Assumptions'!$C$26)+'02_Cash_Flows'!D16-'02_Cash_Flows'!D24-'02_Cash_Flows'!D25-((IF('02_Cash_Flows'!D6>='01_Assumptions'!$C$27,0,'01_Assumptions'!$C$29*$B24*'02_Cash_Flows'!D10))-(IF('02_Cash_Flows'!C6>='01_Assumptions'!$C$27,0,'01_Assumptions'!$C$29*$B24*'02_Cash_Flows'!C10)))+'02_Cash_Flows'!D28 | E24: =($B24*'02_Cash_Flows'!E11+'02_Cash_Flows'!E12-$B24*'02_Cash_Flows'!E13-'02_Cash_Flows'!E14-'02_Cash_Flows'!E16)*(1-'01_Assumptions'!$C$26)+'02_Cash_Flows'!E16-'02_Cash_Flows'!E24-'02_Cash_Flows'!E25-((IF('02_Cash_Flows'!E6>='01_Assumptions'!$C$27,0,'01_Assumptions'!$C$29*$B24*'02_Cash_Flows'!E10))-(IF('02_Cash_Flows'!D6>='01_Assumptions'!$C$27,0,'01_Assumptions'!$C$29*$B24*'02_Cash_Flows'!D10)))+'02_Cash_Flows'!E28 | F24: =($B24*'02_Cash_Flows'!F11+'02_Cash_Flows'!F12-$B24*'02_Cash_Flows'!F13-'02_Cash_Flows'!F14-'02_Cash_Flows'!F16)*(1-'01_Assumptions'!$C$26)+'02_Cash_Flows'!F16-'02_Cash_Flows'!F24-'02_Cash_Flows'!F25-((IF('02_Cash_Flows'!F6>='01_Assumptions'!$C$27,0,'01_Assumptions'!$C$29*$B24*'02_Cash_Flows'!F10))-(IF('02_Cash_Flows'!E6>='01_Assumptions'!$C$27,0,'01_Assumptions'!$C$29*$B24*'02_Cash_Flows'!E10)))+'02_Cash_Flows'!F28 | G24: =($B24*'02_Cash_Flows'!G11+'02_Cash_Flows'!G12-$B24*'02_Cash_Flows'!G13-'02_Cash_Flows'!G14-'02_Cash_Flows'!G16)*(1-'01_Assumptions'!$C$26)+'02_Cash_Flows'!G16-'02_Cash_Flows'!G24-'02_Cash_Flows'!G25-((IF('02_Cash_Flows'!G6>='01_Assumptions'!$C$27,0,'01_Assumptions'!$C$29*$B24*'02_Cash_Flows'!G10))-(IF('02_Cash_Flows'!F6>='01_Assumptions'!$C$27,0,'01_Assumptions'!$C$29*$B24*'02_Cash_Flows'!F10)))+'02_Cash_Flows'!G28 | H24: =($B24*'02_Cash_Flows'!H11+'02_Cash_Flows'!H12-$B24*'02_Cash_Flows'!H13-'02_Cash_Flows'!H14-'02_Cash_Flows'!H16)*(1-'01_Assumptions'!$C$26)+'02_Cash_Flows'!H16-'02_Cash_Flows'!H24-'02_Cash_Flows'!H25-((IF('02_Cash_Flows'!H6>='01_Assumptions'!$C$27,0,'01_Assumptions'!$C$29*$B24*'02_Cash_Flows'!H10))-(IF('02_Cash_Flows'!G6>='01_Assumptions'!$C$27,0,'01_Assumptions'!$C$29*$B24*'02_Cash_Flows'!G10)))+'02_Cash_Flows'!H28 | I24: =($B24*'02_Cash_Flows'!I11+'02_Cash_Flows'!I12-$B24*'02_Cash_Flows'!I13-'02_Cash_Flows'!I14-'02_Cash_Flows'!I16)*(1-'01_Assumptions'!$C$26)+'02_Cash_Flows'!I16-'02_Cash_Flows'!I24-'02_Cash_Flows'!I25-((IF('02_Cash_Flows'!I6>='01_Assumptions'!$C$27,0,'01_Assumptions'!$C$29*$B24*'02_Cash_Flows'!I10))-(IF('02_Cash_Flows'!H6>='01_Assumptions'!$C$27,0,'01_Assumptions'!$C$29*$B24*'02_Cash_Flows'!H10)))+'02_Cash_Flows'!I28 | J24: =($B24*'02_Cash_Flows'!J11+'02_Cash_Flows'!J12-$B24*'02_Cash_Flows'!J13-'02_Cash_Flows'!J14-'02_Cash_Flows'!J16)*(1-'01_Assumptions'!$C$26)+'02_Cash_Flows'!J16-'02_Cash_Flows'!J24-'02_Cash_Flows'!J25-((IF('02_Cash_Flows'!J6>='01_Assumptions'!$C$27,0,'01_Assumptions'!$C$29*$B24*'02_Cash_Flows'!J10))-(IF('02_Cash_Flows'!I6>='01_Assumptions'!$C$27,0,'01_Assumptions'!$C$29*$B24*'02_Cash_Flows'!I10)))+'02_Cash_Flows'!J28 | K24: =($B24*'02_Cash_Flows'!K11+'02_Cash_Flows'!K12-$B24*'02_Cash_Flows'!K13-'02_Cash_Flows'!K14-'02_Cash_Flows'!K16)*(1-'01_Assumptions'!$C$26)+'02_Cash_Flows'!K16-'02_Cash_Flows'!K24-'02_Cash_Flows'!K25-((IF('02_Cash_Flows'!K6>='01_Assumptions'!$C$27,0,'01_Assumptions'!$C$29*$B24*'02_Cash_Flows'!K10))-(IF('02_Cash_Flows'!J6>='01_Assumptions'!$C$27,0,'01_Assumptions'!$C$29*$B24*'02_Cash_Flows'!J10)))+'02_Cash_Flows'!K28
B25: 1.2 | C25: =($B25*'02_Cash_Flows'!C11+'02_Cash_Flows'!C12-$B25*'02_Cash_Flows'!C13-'02_Cash_Flows'!C14-'02_Cash_Flows'!C16)*(1-'01_Assumptions'!$C$26)+'02_Cash_Flows'!C16-'02_Cash_Flows'!C24-'02_Cash_Flows'!C25-(IF('02_Cash_Flows'!C6>='01_Assumptions'!$C$27,0,'01_Assumptions'!$C$29*$B25*'02_Cash_Flows'!C10))+'02_Cash_Flows'!C28 | D25: =($B25*'02_Cash_Flows'!D11+'02_Cash_Flows'!D12-$B25*'02_Cash_Flows'!D13-'02_Cash_Flows'!D14-'02_Cash_Flows'!D16)*(1-'01_Assumptions'!$C$26)+'02_Cash_Flows'!D16-'02_Cash_Flows'!D24-'02_Cash_Flows'!D25-((IF('02_Cash_Flows'!D6>='01_Assumptions'!$C$27,0,'01_Assumptions'!$C$29*$B25*'02_Cash_Flows'!D10))-(IF('02_Cash_Flows'!C6>='01_Assumptions'!$C$27,0,'01_Assumptions'!$C$29*$B25*'02_Cash_Flows'!C10)))+'02_Cash_Flows'!D28 | E25: =($B25*'02_Cash_Flows'!E11+'02_Cash_Flows'!E12-$B25*'02_Cash_Flows'!E13-'02_Cash_Flows'!E14-'02_Cash_Flows'!E16)*(1-'01_Assumptions'!$C$26)+'02_Cash_Flows'!E16-'02_Cash_Flows'!E24-'02_Cash_Flows'!E25-((IF('02_Cash_Flows'!E6>='01_Assumptions'!$C$27,0,'01_Assumptions'!$C$29*$B25*'02_Cash_Flows'!E10))-(IF('02_Cash_Flows'!D6>='01_Assumptions'!$C$27,0,'01_Assumptions'!$C$29*$B25*'02_Cash_Flows'!D10)))+'02_Cash_Flows'!E28 | F25: =($B25*'02_Cash_Flows'!F11+'02_Cash_Flows'!F12-$B25*'02_Cash_Flows'!F13-'02_Cash_Flows'!F14-'02_Cash_Flows'!F16)*(1-'01_Assumptions'!$C$26)+'02_Cash_Flows'!F16-'02_Cash_Flows'!F24-'02_Cash_Flows'!F25-((IF('02_Cash_Flows'!F6>='01_Assumptions'!$C$27,0,'01_Assumptions'!$C$29*$B25*'02_Cash_Flows'!F10))-(IF('02_Cash_Flows'!E6>='01_Assumptions'!$C$27,0,'01_Assumptions'!$C$29*$B25*'02_Cash_Flows'!E10)))+'02_Cash_Flows'!F28 | G25: =($B25*'02_Cash_Flows'!G11+'02_Cash_Flows'!G12-$B25*'02_Cash_Flows'!G13-'02_Cash_Flows'!G14-'02_Cash_Flows'!G16)*(1-'01_Assumptions'!$C$26)+'02_Cash_Flows'!G16-'02_Cash_Flows'!G24-'02_Cash_Flows'!G25-((IF('02_Cash_Flows'!G6>='01_Assumptions'!$C$27,0,'01_Assumptions'!$C$29*$B25*'02_Cash_Flows'!G10))-(IF('02_Cash_Flows'!F6>='01_Assumptions'!$C$27,0,'01_Assumptions'!$C$29*$B25*'02_Cash_Flows'!F10)))+'02_Cash_Flows'!G28 | H25: =($B25*'02_Cash_Flows'!H11+'02_Cash_Flows'!H12-$B25*'02_Cash_Flows'!H13-'02_Cash_Flows'!H14-'02_Cash_Flows'!H16)*(1-'01_Assumptions'!$C$26)+'02_Cash_Flows'!H16-'02_Cash_Flows'!H24-'02_Cash_Flows'!H25-((IF('02_Cash_Flows'!H6>='01_Assumptions'!$C$27,0,'01_Assumptions'!$C$29*$B25*'02_Cash_Flows'!H10))-(IF('02_Cash_Flows'!G6>='01_Assumptions'!$C$27,0,'01_Assumptions'!$C$29*$B25*'02_Cash_Flows'!G10)))+'02_Cash_Flows'!H28 | I25: =($B25*'02_Cash_Flows'!I11+'02_Cash_Flows'!I12-$B25*'02_Cash_Flows'!I13-'02_Cash_Flows'!I14-'02_Cash_Flows'!I16)*(1-'01_Assumptions'!$C$26)+'02_Cash_Flows'!I16-'02_Cash_Flows'!I24-'02_Cash_Flows'!I25-((IF('02_Cash_Flows'!I6>='01_Assumptions'!$C$27,0,'01_Assumptions'!$C$29*$B25*'02_Cash_Flows'!I10))-(IF('02_Cash_Flows'!H6>='01_Assumptions'!$C$27,0,'01_Assumptions'!$C$29*$B25*'02_Cash_Flows'!H10)))+'02_Cash_Flows'!I28 | J25: =($B25*'02_Cash_Flows'!J11+'02_Cash_Flows'!J12-$B25*'02_Cash_Flows'!J13-'02_Cash_Flows'!J14-'02_Cash_Flows'!J16)*(1-'01_Assumptions'!$C$26)+'02_Cash_Flows'!J16-'02_Cash_Flows'!J24-'02_Cash_Flows'!J25-((IF('02_Cash_Flows'!J6>='01_Assumptions'!$C$27,0,'01_Assumptions'!$C$29*$B25*'02_Cash_Flows'!J10))-(IF('02_Cash_Flows'!I6>='01_Assumptions'!$C$27,0,'01_Assumptions'!$C$29*$B25*'02_Cash_Flows'!I10)))+'02_Cash_Flows'!J28 | K25: =($B25*'02_Cash_Flows'!K11+'02_Cash_Flows'!K12-$B25*'02_Cash_Flows'!K13-'02_Cash_Flows'!K14-'02_Cash_Flows'!K16)*(1-'01_Assumptions'!$C$26)+'02_Cash_Flows'!K16-'02_Cash_Flows'!K24-'02_Cash_Flows'!K25-((IF('02_Cash_Flows'!K6>='01_Assumptions'!$C$27,0,'01_Assumptions'!$C$29*$B25*'02_Cash_Flows'!K10))-(IF('02_Cash_Flows'!J6>='01_Assumptions'!$C$27,0,'01_Assumptions'!$C$29*$B25*'02_Cash_Flows'!J10)))+'02_Cash_Flows'!K28
B28: Two-way — NPV ($000s): rows = WACC, columns = volume factor
B29: WACC \ volume | C29: =B21 | D29: =B22 | E29: =B23 | F29: =B24 | G29: =B25
B30: 0.07 | C30: =NPV($B30,D21:K21)+C21 | D30: =NPV($B30,D22:K22)+C22 | E30: =NPV($B30,D23:K23)+C23 | F30: =NPV($B30,D24:K24)+C24 | G30: =NPV($B30,D25:K25)+C25
B31: 0.08 | C31: =NPV($B31,D21:K21)+C21 | D31: =NPV($B31,D22:K22)+C22 | E31: =NPV($B31,D23:K23)+C23 | F31: =NPV($B31,D24:K24)+C24 | G31: =NPV($B31,D25:K25)+C25
B32: 0.095 | C32: =NPV($B32,D21:K21)+C21 | D32: =NPV($B32,D22:K22)+C22 | E32: =NPV($B32,D23:K23)+C23 | F32: =NPV($B32,D24:K24)+C24 | G32: =NPV($B32,D25:K25)+C25
B33: 0.11 | C33: =NPV($B33,D21:K21)+C21 | D33: =NPV($B33,D22:K22)+C22 | E33: =NPV($B33,D23:K23)+C23 | F33: =NPV($B33,D24:K24)+C24 | G33: =NPV($B33,D25:K25)+C25
B34: 0.125 | C34: =NPV($B34,D21:K21)+C21 | D34: =NPV($B34,D22:K22)+C22 | E34: =NPV($B34,D23:K23)+C23 | F34: =NPV($B34,D24:K24)+C24 | G34: =NPV($B34,D25:K25)+C25
B37: Tornado — NPV vs driver (low / high vs current case)
B38: Driver | C38: Low | D38: High | E38: NPV low | F38: NPV high | G38: Swing (high − low)
B39: WACC | C39: 0.08 | D39: 0.11 | E39: =NPV(C39,'02_Cash_Flows'!D29:K29)+'02_Cash_Flows'!C29 | F39: =NPV(D39,'02_Cash_Flows'!D29:K29)+'02_Cash_Flows'!C29 | G39: =F39-E39
B40: Volume factor | C40: =B21 | D40: =B25 | E40: =NPV('01_Assumptions'!C25,D21:K21)+C21 | F40: =NPV('01_Assumptions'!C25,D25:K25)+C25 | G40: =F40-E40
B41: Capex factor (vs current) | C41: 0.9 | D41: 1.15 | E41: ='03_Returns'!C6+(C41-1)*(SUMPRODUCT(-'02_Cash_Flows'!C24:K24+'02_Cash_Flows'!C28:K28+'02_Cash_Flows'!C16:K16*'01_Assumptions'!$C$26,'02_Cash_Flows'!C33:K33)) | F41: ='03_Returns'!C6+(D41-1)*(SUMPRODUCT(-'02_Cash_Flows'!C24:K24+'02_Cash_Flows'!C28:K28+'02_Cash_Flows'!C16:K16*'01_Assumptions'!$C$26,'02_Cash_Flows'!C33:K33)) | G41: =F41-E41
B42: Savings factor (vs current) | C42: 0.8 | D42: 1.2 | E42: ='03_Returns'!C6+(C42-1)*SUMPRODUCT('02_Cash_Flows'!C12:K12*(1-'01_Assumptions'!$C$26),'02_Cash_Flows'!C33:K33) | F42: ='03_Returns'!C6+(D42-1)*SUMPRODUCT('02_Cash_Flows'!C12:K12*(1-'01_Assumptions'!$C$26),'02_Cash_Flows'!C33:K33) | G42: =F42-E42
B43: Contribution $/case (vs current) | C43: 0.85 | D43: 1.1 | E43: ='03_Returns'!C6+(C43-1)*SUMPRODUCT('02_Cash_Flows'!C11:K11*(1-'01_Assumptions'!$C$26),'02_Cash_Flows'!C33:K33) | F43: ='03_Returns'!C6+(D43-1)*SUMPRODUCT('02_Cash_Flows'!C11:K11*(1-'01_Assumptions'!$C$26),'02_Cash_Flows'!C33:K33) | G43: =F43-E43
B45: Volume two-way rebuilds GP, distribution, and NWC with the factor; savings / G&A / D&A / capex stay at the current scenario. Tornado capex, savings, and contribution rows are first-order (scale that line, hold the rest).

Sheet 05_One_Pager
B2: Northline Consumer Products
B3: ='01_Assumptions'!C20
B4: Investment committee one-pager · unlevered · $000s · fictional sample
B6: Snapshot
B7: NPV ($000s) | E7: IRR | H7: Payback (years)
B8: ='03_Returns'!C6 | E8: ='03_Returns'!C7 | H8: ='03_Returns'!C13
B10: WACC | E10: Profitability index | H10: Total capex ($000s)
B11: ='01_Assumptions'!C25 | E11: ='03_Returns'!C12 | H11: ='01_Assumptions'!C59
B13: Recommendation
B14: ='03_Returns'!C18
B15: ='03_Returns'!C19
B17: Key assumptions (live)
B18: Scenario | C18: ='01_Assumptions'!D6 | E18: IRR − WACC | F18: ='03_Returns'!C9
B19: WACC | C19: ='01_Assumptions'!C25 | E19: Discounted payback (yrs) | F19: ='03_Returns'!C14
B20: Tax rate | C20: ='01_Assumptions'!C26 | E20: Sum of FCF ($000s) | F20: ='03_Returns'!C15
B21: Project life (years) | C21: ='01_Assumptions'!C27 | E21: PV of investment ($000s) | F21: ='03_Returns'!C11
B22: Gross capex ($000s) | C22: ='01_Assumptions'!C59
B23: Run-rate volume (000 cases) | C23: ='01_Assumptions'!C47*'01_Assumptions'!C8
B24: Contribution $/case | C24: ='01_Assumptions'!C49*'01_Assumptions'!C10
B25: Run-rate savings ($000s) | C25: ='01_Assumptions'!C56*'01_Assumptions'!C9
B26: NWC % of revenue | C26: ='01_Assumptions'!C29
B27: Salvage ($000s) | C27: ='01_Assumptions'!C60
B29: Unlevered FCF ($000s)
B30: Year | C30: 2026 | D30: 2027 | E30: 2028 | F30: 2029 | G30: 2030 | H30: 2031 | I30: 2032 | J30: 2033 | K30: 2034
B31: FCF | C31: ='02_Cash_Flows'!C29 | D31: ='02_Cash_Flows'!D29 | E31: ='02_Cash_Flows'!E29 | F31: ='02_Cash_Flows'!F29 | G31: ='02_Cash_Flows'!G29 | H31: ='02_Cash_Flows'!H29 | I31: ='02_Cash_Flows'!I29 | J31: ='02_Cash_Flows'!J29 | K31: ='02_Cash_Flows'!K29
B32: Cumulative | C32: ='02_Cash_Flows'!C30 | D32: ='02_Cash_Flows'!D30 | E32: ='02_Cash_Flows'!E30 | F32: ='02_Cash_Flows'!F30 | G32: ='02_Cash_Flows'!G30 | H32: ='02_Cash_Flows'!H30 | I32: ='02_Cash_Flows'!I30 | J32: ='02_Cash_Flows'!J30 | K32: ='02_Cash_Flows'!K30
B49: NPV vs WACC (from 04_Sensitivity) | E49: How to inherit
B50: ='04_Sensitivity'!B12 | C50: ='04_Sensitivity'!C12 | E50: Change yellow cells on 01_Assumptions. Live case is whatever scenario 1/2/3 is selected. Do not type over black cells.
B51: ='04_Sensitivity'!B13 | C51: ='04_Sensitivity'!C13
B52: ='04_Sensitivity'!B14 | C52: ='04_Sensitivity'!C14
B53: ='04_Sensitivity'!B15 | C53: ='04_Sensitivity'!C15
B54: ='04_Sensitivity'!B16 | C54: ='04_Sensitivity'!C16
B56: All sample numbers are fictional. Built for a public GitHub portfolio — no employer data.

Sheet 06_Data_Dictionary
B2: Data dictionary
B3: Field definitions so another analyst can inherit the file.
B5: Field | C5: Tab | D5: Definition
B6: Scenario | C6: 01_Assumptions | D6: 1 Base / 2 Upside / 3 Downside. Indexes the factor table and scales capex, volume, savings, and contribution $/case.
B7: Capex / volume / savings / contribution factors | C7: 01_Assumptions | D7: Applied to gross capex spend, volume, run-rate savings, and contribution per case.
B8: WACC | C8: 01_Assumptions | D8: Unlevered project hurdle. Year-end discounting of FCF. Sample 9.5%.
B9: Tax rate | C9: 01_Assumptions | D9: Applied to EBIT. Negative EBIT produces a tax shield (assumes the firm has other taxable income).
B10: Project life | C10: 01_Assumptions | D10: Operating and D&A years from COD (t = 1). Sample 8 years (2027–2034). t = 0 is 2026 spend.
B11: Salvage % of gross capex | C11: 01_Assumptions | D11: Cash inflow in the final year. Straight-line D&A is charged on (gross capex − salvage), so book value = salvage and the inflow is untaxed.
B12: NWC % of incremental revenue | C12: 01_Assumptions | D12: NWC balance = % × incremental revenue. Released (balance → 0) in the final project year.
B13: Gross capex timing | C13: 01_Assumptions | D13: Equipment, installation, and spares by year, then × capex factor. Sample spend in 2026–2027.
B14: Maintenance capex | C14: 01_Assumptions | D14: Sustaining capex after COD. Not scaled by the scenario capex factor.
B15: Volume ramp | C15: 01_Assumptions | D15: Share of run-rate volume lift by year, then × volume factor.
B16: Savings ramp | C16: 01_Assumptions | D16: Share of run-rate cost savings by year, then × savings factor.
... B32: Units | C32: All | D32: Dollars in $000s. Volume in 000 cases. Prices and contribution in $ per case. Rates in %.
B33: All sample numbers are fictional. Built for a public GitHub portfolio — no employer data.
